<?xml version="1.0" encoding="utf-8"?>
<robot name="partnet_3167991b1c87967ac59350d819542ec7">
 <link name="base"/>
 <link name="link_0">
  <visual name="cabinet_door_surface-16">
   <origin xyz="-0.4738178842997721 -0.38418192458328726 -0.4181071925928191"/>
   <geometry>
    <mesh filename="textured_objs/original-56.obj"/>
   </geometry>
  </visual>
  <visual name="cabinet_door_surface-16">
   <origin xyz="-0.4738178842997721 -0.38418192458328726 -0.4181071925928191"/>
   <geometry>
    <mesh filename="textured_objs/original-60.obj"/>
   </geometry>
  </visual>
  <visual name="cabinet_door_surface-16">
   <origin xyz="-0.4738178842997721 -0.38418192458328726 -0.4181071925928191"/>
   <geometry>
    <mesh filename="textured_objs/original-50.obj"/>
   </geometry>
  </visual>
  <visual name="cabinet_door_surface-16">
   <origin xyz="-0.4738178842997721 -0.38418192458328726 -0.4181071925928191"/>
   <geometry>
    <mesh filename="textured_objs/original-51.obj"/>
   </geometry>
  </visual>
  <visual name="cabinet_door_surface-16">
   <origin xyz="-0.4738178842997721 -0.38418192458328726 -0.4181071925928191"/>
   <geometry>
    <mesh filename="textured_objs/original-57.obj"/>
   </geometry>
  </visual>
  <visual name="cabinet_door_surface-16">
   <origin xyz="-0.4738178842997721 -0.38418192458328726 -0.4181071925928191"/>
   <geometry>
    <mesh filename="textured_objs/original-54.obj"/>
   </geometry>
  </visual>
  <visual name="cabinet_door_surface-16">
   <origin xyz="-0.4738178842997721 -0.38418192458328726 -0.4181071925928191"/>
   <geometry>
    <mesh filename="textured_objs/original-55.obj"/>
   </geometry>
  </visual>
  <visual name="cabinet_door_surface-16">
   <origin xyz="-0.4738178842997721 -0.38418192458328726 -0.4181071925928191"/>
   <geometry>
    <mesh filename="textured_objs/original-53.obj"/>
   </geometry>
  </visual>
  <visual name="cabinet_door_surface-16">
   <origin xyz="-0.4738178842997721 -0.38418192458328726 -0.4181071925928191"/>
   <geometry>
    <mesh filename="textured_objs/original-52.obj"/>
   </geometry>
  </visual>
  <visual name="cabinet_door_surface-16">
   <origin xyz="-0.4738178842997721 -0.38418192458328726 -0.4181071925928191"/>
   <geometry>
    <mesh filename="textured_objs/original-59.obj"/>
   </geometry>
  </visual>
  <visual name="handle-17">
   <origin xyz="-0.4738178842997721 -0.38418192458328726 -0.4181071925928191"/>
   <geometry>
    <mesh filename="textured_objs/original-61.obj"/>
   </geometry>
  </visual>
  <collision>
   <origin rpy="5.9604625235475695e-08 1.78813893469985e-07 -5.9604625235475695e-08" xyz="-0.47381868958473206 -0.3841826319694519 -0.41810810565948486"/>
   <geometry>
    <mesh filename="cvx_objs/link_0.obj"/>
   </geometry>
  </collision>
 </link>
 <joint name="joint_0" type="revolute">
  <origin xyz="0.4738178842997721 0.38418192458328726 0.4181071925928191"/>
  <axis xyz="0 1 0"/>
  <child link="link_0"/>
  <parent link="link_2"/>
  <limit lower="0.0" upper="1.6587609210954108"/>
 </joint>
 <link name="link_1">
  <visual name="drawer_side-9">
   <origin xyz="-0.0021619365588228176 -0.5549306647458297 0.3783000111579897"/>
   <geometry>
    <mesh filename="textured_objs/original-30.obj"/>
   </geometry>
  </visual>
  <visual name="drawer_side-10">
   <origin xyz="-0.0021619365588228176 -0.5549306647458297 0.3783000111579897"/>
   <geometry>
    <mesh filename="textured_objs/original-25.obj"/>
   </geometry>
  </visual>
  <visual name="drawer_back-11">
   <origin xyz="-0.0021619365588228176 -0.5549306647458297 0.3783000111579897"/>
   <geometry>
    <mesh filename="textured_objs/original-31.obj"/>
   </geometry>
  </visual>
  <visual name="drawer_bottom-12">
   <origin xyz="-0.0021619365588228176 -0.5549306647458297 0.3783000111579897"/>
   <geometry>
    <mesh filename="textured_objs/original-29.obj"/>
   </geometry>
  </visual>
  <visual name="drawer_bottom-12">
   <origin xyz="-0.0021619365588228176 -0.5549306647458297 0.3783000111579897"/>
   <geometry>
    <mesh filename="textured_objs/original-28.obj"/>
   </geometry>
  </visual>
  <visual name="drawer_front-13">
   <origin xyz="-0.0021619365588228176 -0.5549306647458297 0.3783000111579897"/>
   <geometry>
    <mesh filename="textured_objs/original-26.obj"/>
   </geometry>
  </visual>
  <visual name="drawer_front-13">
   <origin xyz="-0.0021619365588228176 -0.5549306647458297 0.3783000111579897"/>
   <geometry>
    <mesh filename="textured_objs/original-34.obj"/>
   </geometry>
  </visual>
  <visual name="drawer_front-13">
   <origin xyz="-0.0021619365588228176 -0.5549306647458297 0.3783000111579897"/>
   <geometry>
    <mesh filename="textured_objs/original-36.obj"/>
   </geometry>
  </visual>
  <visual name="drawer_front-13">
   <origin xyz="-0.0021619365588228176 -0.5549306647458297 0.3783000111579897"/>
   <geometry>
    <mesh filename="textured_objs/original-43.obj"/>
   </geometry>
  </visual>
  <visual name="drawer_front-13">
   <origin xyz="-0.0021619365588228176 -0.5549306647458297 0.3783000111579897"/>
   <geometry>
    <mesh filename="textured_objs/original-38.obj"/>
   </geometry>
  </visual>
  <visual name="drawer_front-13">
   <origin xyz="-0.0021619365588228176 -0.5549306647458297 0.3783000111579897"/>
   <geometry>
    <mesh filename="textured_objs/original-39.obj"/>
   </geometry>
  </visual>
  <visual name="drawer_front-13">
   <origin xyz="-0.0021619365588228176 -0.5549306647458297 0.3783000111579897"/>
   <geometry>
    <mesh filename="textured_objs/original-35.obj"/>
   </geometry>
  </visual>
  <visual name="drawer_front-13">
   <origin xyz="-0.0021619365588228176 -0.5549306647458297 0.3783000111579897"/>
   <geometry>
    <mesh filename="textured_objs/original-41.obj"/>
   </geometry>
  </visual>
  <visual name="drawer_front-13">
   <origin xyz="-0.0021619365588228176 -0.5549306647458297 0.3783000111579897"/>
   <geometry>
    <mesh filename="textured_objs/original-40.obj"/>
   </geometry>
  </visual>
  <visual name="drawer_front-13">
   <origin xyz="-0.0021619365588228176 -0.5549306647458297 0.3783000111579897"/>
   <geometry>
    <mesh filename="textured_objs/original-37.obj"/>
   </geometry>
  </visual>
  <visual name="drawer_front-13">
   <origin xyz="-0.0021619365588228176 -0.5549306647458297 0.3783000111579897"/>
   <geometry>
    <mesh filename="textured_objs/original-44.obj"/>
   </geometry>
  </visual>
  <visual name="other_leaf-15">
   <origin xyz="-0.0021619365588228176 -0.5549306647458297 0.3783000111579897"/>
   <geometry>
    <mesh filename="textured_objs/original-32.obj"/>
   </geometry>
  </visual>
  <visual name="handle-7">
   <origin xyz="-0.0021619365588228176 -0.5549306647458297 0.3783000111579897"/>
   <geometry>
    <mesh filename="textured_objs/original-46.obj"/>
   </geometry>
  </visual>
  <visual name="handle-7">
   <origin xyz="-0.0021619365588228176 -0.5549306647458297 0.3783000111579897"/>
   <geometry>
    <mesh filename="textured_objs/original-47.obj"/>
   </geometry>
  </visual>
  <visual name="handle-7">
   <origin xyz="-0.0021619365588228176 -0.5549306647458297 0.3783000111579897"/>
   <geometry>
    <mesh filename="textured_objs/original-48.obj"/>
   </geometry>
  </visual>
  <collision>
   <origin rpy="-2.384185506798621e-07 -1.4210851327071022e-14 -1.192092753399302e-07" xyz="-0.0021620169281959534 -0.5549314022064209 0.378300279378891"/>
   <geometry>
    <mesh filename="cvx_objs/link_1.obj"/>
   </geometry>
  </collision>
 </link>
 <joint name="joint_1" type="prismatic">
  <origin xyz="0.0021619365588228176 0.5549306647458297 -0.3783000111579897"/>
  <axis xyz="0 0 1"/>
  <child link="link_1"/>
  <parent link="link_2"/>
  <limit lower="0" upper="0.536"/>
 </joint>
 <link name="link_2">
  <visual name="shelf-34">
   <origin xyz="0 0 0"/>
   <geometry>
    <mesh filename="textured_objs/original-2.obj"/>
   </geometry>
  </visual>
  <visual name="frame_vertical_bar-27">
   <origin xyz="0 0 0"/>
   <geometry>
    <mesh filename="textured_objs/original-8.obj"/>
   </geometry>
  </visual>
  <visual name="frame_vertical_bar-28">
   <origin xyz="0 0 0"/>
   <geometry>
    <mesh filename="textured_objs/original-4.obj"/>
   </geometry>
  </visual>
  <visual name="frame_horizontal_bar-29">
   <origin xyz="0 0 0"/>
   <geometry>
    <mesh filename="textured_objs/original-5.obj"/>
   </geometry>
  </visual>
  <visual name="frame_horizontal_bar-30">
   <origin xyz="0 0 0"/>
   <geometry>
    <mesh filename="textured_objs/original-7.obj"/>
   </geometry>
  </visual>
  <visual name="frame_horizontal_bar-31">
   <origin xyz="0 0 0"/>
   <geometry>
    <mesh filename="textured_objs/original-22.obj"/>
   </geometry>
  </visual>
  <visual name="frame_horizontal_bar-32">
   <origin xyz="0 0 0"/>
   <geometry>
    <mesh filename="textured_objs/original-21.obj"/>
   </geometry>
  </visual>
  <visual name="frame_horizontal_bar-33">
   <origin xyz="0 0 0"/>
   <geometry>
    <mesh filename="textured_objs/original-18.obj"/>
   </geometry>
  </visual>
  <visual name="vertical_side_panel-35">
   <origin xyz="0 0 0"/>
   <geometry>
    <mesh filename="textured_objs/original-12.obj"/>
   </geometry>
  </visual>
  <visual name="vertical_side_panel-35">
   <origin xyz="0 0 0"/>
   <geometry>
    <mesh filename="textured_objs/original-11.obj"/>
   </geometry>
  </visual>
  <visual name="vertical_side_panel-36">
   <origin xyz="0 0 0"/>
   <geometry>
    <mesh filename="textured_objs/original-16.obj"/>
   </geometry>
  </visual>
  <visual name="vertical_side_panel-36">
   <origin xyz="0 0 0"/>
   <geometry>
    <mesh filename="textured_objs/original-15.obj"/>
   </geometry>
  </visual>
  <visual name="back_panel-37">
   <origin xyz="0 0 0"/>
   <geometry>
    <mesh filename="textured_objs/original-6.obj"/>
   </geometry>
  </visual>
  <visual name="bottom_panel-38">
   <origin xyz="0 0 0"/>
   <geometry>
    <mesh filename="textured_objs/original-3.obj"/>
   </geometry>
  </visual>
  <visual name="frame_horizontal_bar-39">
   <origin xyz="0 0 0"/>
   <geometry>
    <mesh filename="textured_objs/original-9.obj"/>
   </geometry>
  </visual>
  <visual name="other_leaf-41">
   <origin xyz="0 0 0"/>
   <geometry>
    <mesh filename="textured_objs/original-62.obj"/>
   </geometry>
  </visual>
  <visual name="base_side_panel-19">
   <origin xyz="0 0 0"/>
   <geometry>
    <mesh filename="textured_objs/original-17.obj"/>
   </geometry>
  </visual>
  <visual name="base_side_panel-20">
   <origin xyz="0 0 0"/>
   <geometry>
    <mesh filename="textured_objs/original-19.obj"/>
   </geometry>
  </visual>
  <visual name="base_side_panel-21">
   <origin xyz="0 0 0"/>
   <geometry>
    <mesh filename="textured_objs/original-13.obj"/>
   </geometry>
  </visual>
  <visual name="base_side_panel-22">
   <origin xyz="0 0 0"/>
   <geometry>
    <mesh filename="textured_objs/original-20.obj"/>
   </geometry>
  </visual>
  <collision>
   <origin rpy="0.0 -0.0 0.0" xyz="-0.0 -0.0 -0.0"/>
   <geometry>
    <mesh filename="cvx_objs/link_2.obj"/>
   </geometry>
  </collision>
 </link>
 <joint name="joint_2" type="fixed">
  <origin rpy="1.570796326794897 0 -1.570796326794897" xyz="0 0 0"/>
  <child link="link_2"/>
  <parent link="base"/>
 </joint>
</robot>